<?xml version="1.0" encoding="UTF-8"?>
<testng-results skipped="0" failed="1" total="2" passed="1">
  <reporter-output>
  </reporter-output>
  <suite name="Default suite" duration-ms="24" started-at="2022-02-12T19:06:18Z" finished-at="2022-02-12T19:06:18Z">
    <groups>
    </groups>
    <test name="Default test" duration-ms="24" started-at="2022-02-12T19:06:18Z" finished-at="2022-02-12T19:06:18Z">
      <class name="package1.templateFive">
        <test-method status="PASS" signature="setupTest()[pri:0, instance:package1.templateFive@1e730495]" name="setupTest" is-config="true" duration-ms="5" started-at="2022-02-12T14:06:18Z" finished-at="2022-02-12T14:06:18Z">
          <reporter-output>
          </reporter-output>
        </test-method> <!-- setupTest -->
        <test-method status="PASS" signature="atest()[pri:0, instance:package1.templateFive@1e730495]" name="atest" duration-ms="5" started-at="2022-02-12T14:06:18Z" finished-at="2022-02-12T14:06:18Z">
          <reporter-output>
          </reporter-output>
        </test-method> <!-- atest -->
        <test-method status="FAIL" signature="btest()[pri:0, instance:package1.templateFive@1e730495]" name="btest" duration-ms="1" started-at="2022-02-12T14:06:18Z" finished-at="2022-02-12T14:06:18Z">
          <exception class="java.lang.AssertionError">
            <message>
              <![CDATA[expected [false] but found [true]]]>
            </message>
            <full-stacktrace>
              <![CDATA[java.lang.AssertionError: expected [false] but found [true]
	at org.testng.Assert.fail(Assert.java:94)
	at org.testng.Assert.failNotEquals(Assert.java:496)
	at org.testng.Assert.assertFalse(Assert.java:63)
	at org.testng.Assert.assertFalse(Assert.java:73)
	at package1.templateFive.btest(templateFive.java:47)
	at sun.reflect.NativeMethodAccessorImpl.invoke0(Native Method)
	at sun.reflect.NativeMethodAccessorImpl.invoke(Unknown Source)
	at sun.reflect.DelegatingMethodAccessorImpl.invoke(Unknown Source)
	at java.lang.reflect.Method.invoke(Unknown Source)
	at org.testng.internal.MethodInvocationHelper.invokeMethod(MethodInvocationHelper.java:85)
	at org.testng.internal.Invoker.invokeMethod(Invoker.java:639)
	at org.testng.internal.Invoker.invokeTestMethod(Invoker.java:816)
	at org.testng.internal.Invoker.invokeTestMethods(Invoker.java:1124)
	at org.testng.internal.TestMethodWorker.invokeTestMethods(TestMethodWorker.java:125)
	at org.testng.internal.TestMethodWorker.run(TestMethodWorker.java:108)
	at org.testng.TestRunner.privateRun(TestRunner.java:774)
	at org.testng.TestRunner.run(TestRunner.java:624)
	at org.testng.SuiteRunner.runTest(SuiteRunner.java:359)
	at org.testng.SuiteRunner.runSequentially(SuiteRunner.java:354)
	at org.testng.SuiteRunner.privateRun(SuiteRunner.java:312)
	at org.testng.SuiteRunner.run(SuiteRunner.java:261)
	at org.testng.SuiteRunnerWorker.runSuite(SuiteRunnerWorker.java:52)
	at org.testng.SuiteRunnerWorker.run(SuiteRunnerWorker.java:86)
	at org.testng.TestNG.runSuitesSequentially(TestNG.java:1215)
	at org.testng.TestNG.runSuitesLocally(TestNG.java:1140)
	at org.testng.TestNG.run(TestNG.java:1048)
	at org.testng.remote.AbstractRemoteTestNG.run(AbstractRemoteTestNG.java:115)
	at org.testng.remote.RemoteTestNG.initAndRun(RemoteTestNG.java:251)
	at org.testng.remote.RemoteTestNG.main(RemoteTestNG.java:77)
]]>
            </full-stacktrace>
          </exception> <!-- java.lang.AssertionError -->
          <reporter-output>
          </reporter-output>
        </test-method> <!-- btest -->
        <test-method status="PASS" signature="endTest()[pri:0, instance:package1.templateFive@1e730495]" name="endTest" is-config="true" duration-ms="1" started-at="2022-02-12T14:06:18Z" finished-at="2022-02-12T14:06:18Z">
          <reporter-output>
          </reporter-output>
        </test-method> <!-- endTest -->
      </class> <!-- package1.templateFive -->
    </test> <!-- Default test -->
  </suite> <!-- Default suite -->
</testng-results>
